<?xml version="1.0" encoding="UTF-8"?>
<testng-results skipped="4" failed="2" total="7" passed="1">
  <reporter-output>
  </reporter-output>
  <suite name="RetryFailedTestSuite" duration-ms="82" started-at="2019-08-21T17:15:44Z" finished-at="2019-08-21T17:15:44Z">
    <groups>
    </groups>
    <test name="RetryMultipleFailedTestCases" duration-ms="82" started-at="2019-08-21T17:15:44Z" finished-at="2019-08-21T17:15:44Z">
      <class name="MyTests.RunTimeTests">
        <test-method status="SKIP" signature="Test1()[pri:0, instance:MyTests.RunTimeTests@66d2e7d9]" name="Test1" duration-ms="18" started-at="2019-08-21T22:45:44Z" finished-at="2019-08-21T22:45:44Z">
          <exception class="java.lang.AssertionError">
            <message>
              <![CDATA[expected [true] but found [false]]]>
            </message>
            <full-stacktrace>
              <![CDATA[java.lang.AssertionError: expected [true] but found [false]
	at org.testng.Assert.fail(Assert.java:94)
	at org.testng.Assert.failNotEquals(Assert.java:513)
	at org.testng.Assert.assertEqualsImpl(Assert.java:135)
	at org.testng.Assert.assertEquals(Assert.java:116)
	at org.testng.Assert.assertEquals(Assert.java:305)
	at org.testng.Assert.assertEquals(Assert.java:315)
	at MyTests.RunTimeTests.Test1(RunTimeTests.java:12)
	at sun.reflect.NativeMethodAccessorImpl.invoke0(Native Method)
	at sun.reflect.NativeMethodAccessorImpl.invoke(NativeMethodAccessorImpl.java:62)
	at sun.reflect.DelegatingMethodAccessorImpl.invoke(DelegatingMethodAccessorImpl.java:43)
	at java.lang.reflect.Method.invoke(Method.java:498)
	at org.testng.internal.MethodInvocationHelper.invokeMethod(MethodInvocationHelper.java:86)
	at org.testng.internal.Invoker.invokeMethod(Invoker.java:646)
	at org.testng.internal.Invoker.invokeTestMethod(Invoker.java:823)
	at org.testng.internal.Invoker.invokeTestMethods(Invoker.java:1131)
	at org.testng.internal.TestMethodWorker.invokeTestMethods(TestMethodWorker.java:129)
	at org.testng.internal.TestMethodWorker.run(TestMethodWorker.java:112)
	at org.testng.TestRunner.privateRun(TestRunner.java:778)
	at org.testng.TestRunner.run(TestRunner.java:632)
	at org.testng.SuiteRunner.runTest(SuiteRunner.java:366)
	at org.testng.SuiteRunner.runSequentially(SuiteRunner.java:361)
	at org.testng.SuiteRunner.privateRun(SuiteRunner.java:319)
	at org.testng.SuiteRunner.run(SuiteRunner.java:268)
	at org.testng.SuiteRunnerWorker.runSuite(SuiteRunnerWorker.java:52)
	at org.testng.SuiteRunnerWorker.run(SuiteRunnerWorker.java:86)
	at org.testng.TestNG.runSuitesSequentially(TestNG.java:1225)
	at org.testng.TestNG.runSuitesLocally(TestNG.java:1150)
	at org.testng.TestNG.runSuites(TestNG.java:1075)
	at org.testng.TestNG.run(TestNG.java:1047)
	at org.testng.remote.AbstractRemoteTestNG.run(AbstractRemoteTestNG.java:126)
	at org.testng.remote.RemoteTestNG.initAndRun(RemoteTestNG.java:137)
	at org.testng.remote.RemoteTestNG.main(RemoteTestNG.java:58)
]]>
            </full-stacktrace>
          </exception> <!-- java.lang.AssertionError -->
          <reporter-output>
          </reporter-output>
        </test-method> <!-- Test1 -->
        <test-method status="SKIP" signature="Test1()[pri:0, instance:MyTests.RunTimeTests@66d2e7d9]" name="Test1" duration-ms="3" started-at="2019-08-21T22:45:44Z" finished-at="2019-08-21T22:45:44Z">
          <exception class="java.lang.AssertionError">
            <message>
              <![CDATA[expected [true] but found [false]]]>
            </message>
            <full-stacktrace>
              <![CDATA[java.lang.AssertionError: expected [true] but found [false]
	at org.testng.Assert.fail(Assert.java:94)
	at org.testng.Assert.failNotEquals(Assert.java:513)
	at org.testng.Assert.assertEqualsImpl(Assert.java:135)
	at org.testng.Assert.assertEquals(Assert.java:116)
	at org.testng.Assert.assertEquals(Assert.java:305)
	at org.testng.Assert.assertEquals(Assert.java:315)
	at MyTests.RunTimeTests.Test1(RunTimeTests.java:12)
	at sun.reflect.NativeMethodAccessorImpl.invoke0(Native Method)
	at sun.reflect.NativeMethodAccessorImpl.invoke(NativeMethodAccessorImpl.java:62)
	at sun.reflect.DelegatingMethodAccessorImpl.invoke(DelegatingMethodAccessorImpl.java:43)
	at java.lang.reflect.Method.invoke(Method.java:498)
	at org.testng.internal.MethodInvocationHelper.invokeMethod(MethodInvocationHelper.java:86)
	at org.testng.internal.Invoker.invokeMethod(Invoker.java:646)
	at org.testng.internal.Invoker.retryFailed(Invoker.java:970)
	at org.testng.internal.Invoker.invokeTestMethods(Invoker.java:1149)
	at org.testng.internal.TestMethodWorker.invokeTestMethods(TestMethodWorker.java:129)
	at org.testng.internal.TestMethodWorker.run(TestMethodWorker.java:112)
	at org.testng.TestRunner.privateRun(TestRunner.java:778)
	at org.testng.TestRunner.run(TestRunner.java:632)
	at org.testng.SuiteRunner.runTest(SuiteRunner.java:366)
	at org.testng.SuiteRunner.runSequentially(SuiteRunner.java:361)
	at org.testng.SuiteRunner.privateRun(SuiteRunner.java:319)
	at org.testng.SuiteRunner.run(SuiteRunner.java:268)
	at org.testng.SuiteRunnerWorker.runSuite(SuiteRunnerWorker.java:52)
	at org.testng.SuiteRunnerWorker.run(SuiteRunnerWorker.java:86)
	at org.testng.TestNG.runSuitesSequentially(TestNG.java:1225)
	at org.testng.TestNG.runSuitesLocally(TestNG.java:1150)
	at org.testng.TestNG.runSuites(TestNG.java:1075)
	at org.testng.TestNG.run(TestNG.java:1047)
	at org.testng.remote.AbstractRemoteTestNG.run(AbstractRemoteTestNG.java:126)
	at org.testng.remote.RemoteTestNG.initAndRun(RemoteTestNG.java:137)
	at org.testng.remote.RemoteTestNG.main(RemoteTestNG.java:58)
]]>
            </full-stacktrace>
          </exception> <!-- java.lang.AssertionError -->
          <reporter-output>
          </reporter-output>
        </test-method> <!-- Test1 -->
        <test-method status="FAIL" signature="Test1()[pri:0, instance:MyTests.RunTimeTests@66d2e7d9]" name="Test1" duration-ms="4" started-at="2019-08-21T22:45:44Z" finished-at="2019-08-21T22:45:44Z">
          <exception class="java.lang.AssertionError">
            <message>
              <![CDATA[expected [true] but found [false]]]>
            </message>
            <full-stacktrace>
              <![CDATA[java.lang.AssertionError: expected [true] but found [false]
	at org.testng.Assert.fail(Assert.java:94)
	at org.testng.Assert.failNotEquals(Assert.java:513)
	at org.testng.Assert.assertEqualsImpl(Assert.java:135)
	at org.testng.Assert.assertEquals(Assert.java:116)
	at org.testng.Assert.assertEquals(Assert.java:305)
	at org.testng.Assert.assertEquals(Assert.java:315)
	at MyTests.RunTimeTests.Test1(RunTimeTests.java:12)
	at sun.reflect.NativeMethodAccessorImpl.invoke0(Native Method)
	at sun.reflect.NativeMethodAccessorImpl.invoke(NativeMethodAccessorImpl.java:62)
	at sun.reflect.DelegatingMethodAccessorImpl.invoke(DelegatingMethodAccessorImpl.java:43)
	at java.lang.reflect.Method.invoke(Method.java:498)
	at org.testng.internal.MethodInvocationHelper.invokeMethod(MethodInvocationHelper.java:86)
	at org.testng.internal.Invoker.invokeMethod(Invoker.java:646)
	at org.testng.internal.Invoker.retryFailed(Invoker.java:970)
	at org.testng.internal.Invoker.invokeTestMethods(Invoker.java:1149)
	at org.testng.internal.TestMethodWorker.invokeTestMethods(TestMethodWorker.java:129)
	at org.testng.internal.TestMethodWorker.run(TestMethodWorker.java:112)
	at org.testng.TestRunner.privateRun(TestRunner.java:778)
	at org.testng.TestRunner.run(TestRunner.java:632)
	at org.testng.SuiteRunner.runTest(SuiteRunner.java:366)
	at org.testng.SuiteRunner.runSequentially(SuiteRunner.java:361)
	at org.testng.SuiteRunner.privateRun(SuiteRunner.java:319)
	at org.testng.SuiteRunner.run(SuiteRunner.java:268)
	at org.testng.SuiteRunnerWorker.runSuite(SuiteRunnerWorker.java:52)
	at org.testng.SuiteRunnerWorker.run(SuiteRunnerWorker.java:86)
	at org.testng.TestNG.runSuitesSequentially(TestNG.java:1225)
	at org.testng.TestNG.runSuitesLocally(TestNG.java:1150)
	at org.testng.TestNG.runSuites(TestNG.java:1075)
	at org.testng.TestNG.run(TestNG.java:1047)
	at org.testng.remote.AbstractRemoteTestNG.run(AbstractRemoteTestNG.java:126)
	at org.testng.remote.RemoteTestNG.initAndRun(RemoteTestNG.java:137)
	at org.testng.remote.RemoteTestNG.main(RemoteTestNG.java:58)
]]>
            </full-stacktrace>
          </exception> <!-- java.lang.AssertionError -->
          <reporter-output>
          </reporter-output>
        </test-method> <!-- Test1 -->
        <test-method status="SKIP" signature="Test2()[pri:0, instance:MyTests.RunTimeTests@66d2e7d9]" name="Test2" duration-ms="3" started-at="2019-08-21T22:45:44Z" finished-at="2019-08-21T22:45:44Z">
          <exception class="java.lang.AssertionError">
            <message>
              <![CDATA[expected [true] but found [false]]]>
            </message>
            <full-stacktrace>
              <![CDATA[java.lang.AssertionError: expected [true] but found [false]
	at org.testng.Assert.fail(Assert.java:94)
	at org.testng.Assert.failNotEquals(Assert.java:513)
	at org.testng.Assert.assertEqualsImpl(Assert.java:135)
	at org.testng.Assert.assertEquals(Assert.java:116)
	at org.testng.Assert.assertEquals(Assert.java:305)
	at org.testng.Assert.assertEquals(Assert.java:315)
	at MyTests.RunTimeTests.Test2(RunTimeTests.java:18)
	at sun.reflect.NativeMethodAccessorImpl.invoke0(Native Method)
	at sun.reflect.NativeMethodAccessorImpl.invoke(NativeMethodAccessorImpl.java:62)
	at sun.reflect.DelegatingMethodAccessorImpl.invoke(DelegatingMethodAccessorImpl.java:43)
	at java.lang.reflect.Method.invoke(Method.java:498)
	at org.testng.internal.MethodInvocationHelper.invokeMethod(MethodInvocationHelper.java:86)
	at org.testng.internal.Invoker.invokeMethod(Invoker.java:646)
	at org.testng.internal.Invoker.invokeTestMethod(Invoker.java:823)
	at org.testng.internal.Invoker.invokeTestMethods(Invoker.java:1131)
	at org.testng.internal.TestMethodWorker.invokeTestMethods(TestMethodWorker.java:129)
	at org.testng.internal.TestMethodWorker.run(TestMethodWorker.java:112)
	at org.testng.TestRunner.privateRun(TestRunner.java:778)
	at org.testng.TestRunner.run(TestRunner.java:632)
	at org.testng.SuiteRunner.runTest(SuiteRunner.java:366)
	at org.testng.SuiteRunner.runSequentially(SuiteRunner.java:361)
	at org.testng.SuiteRunner.privateRun(SuiteRunner.java:319)
	at org.testng.SuiteRunner.run(SuiteRunner.java:268)
	at org.testng.SuiteRunnerWorker.runSuite(SuiteRunnerWorker.java:52)
	at org.testng.SuiteRunnerWorker.run(SuiteRunnerWorker.java:86)
	at org.testng.TestNG.runSuitesSequentially(TestNG.java:1225)
	at org.testng.TestNG.runSuitesLocally(TestNG.java:1150)
	at org.testng.TestNG.runSuites(TestNG.java:1075)
	at org.testng.TestNG.run(TestNG.java:1047)
	at org.testng.remote.AbstractRemoteTestNG.run(AbstractRemoteTestNG.java:126)
	at org.testng.remote.RemoteTestNG.initAndRun(RemoteTestNG.java:137)
	at org.testng.remote.RemoteTestNG.main(RemoteTestNG.java:58)
]]>
            </full-stacktrace>
          </exception> <!-- java.lang.AssertionError -->
          <reporter-output>
          </reporter-output>
        </test-method> <!-- Test2 -->
        <test-method status="SKIP" signature="Test2()[pri:0, instance:MyTests.RunTimeTests@66d2e7d9]" name="Test2" duration-ms="2" started-at="2019-08-21T22:45:44Z" finished-at="2019-08-21T22:45:44Z">
          <exception class="java.lang.AssertionError">
            <message>
              <![CDATA[expected [true] but found [false]]]>
            </message>
            <full-stacktrace>
              <![CDATA[java.lang.AssertionError: expected [true] but found [false]
	at org.testng.Assert.fail(Assert.java:94)
	at org.testng.Assert.failNotEquals(Assert.java:513)
	at org.testng.Assert.assertEqualsImpl(Assert.java:135)
	at org.testng.Assert.assertEquals(Assert.java:116)
	at org.testng.Assert.assertEquals(Assert.java:305)
	at org.testng.Assert.assertEquals(Assert.java:315)
	at MyTests.RunTimeTests.Test2(RunTimeTests.java:18)
	at sun.reflect.NativeMethodAccessorImpl.invoke0(Native Method)
	at sun.reflect.NativeMethodAccessorImpl.invoke(NativeMethodAccessorImpl.java:62)
	at sun.reflect.DelegatingMethodAccessorImpl.invoke(DelegatingMethodAccessorImpl.java:43)
	at java.lang.reflect.Method.invoke(Method.java:498)
	at org.testng.internal.MethodInvocationHelper.invokeMethod(MethodInvocationHelper.java:86)
	at org.testng.internal.Invoker.invokeMethod(Invoker.java:646)
	at org.testng.internal.Invoker.retryFailed(Invoker.java:970)
	at org.testng.internal.Invoker.invokeTestMethods(Invoker.java:1149)
	at org.testng.internal.TestMethodWorker.invokeTestMethods(TestMethodWorker.java:129)
	at org.testng.internal.TestMethodWorker.run(TestMethodWorker.java:112)
	at org.testng.TestRunner.privateRun(TestRunner.java:778)
	at org.testng.TestRunner.run(TestRunner.java:632)
	at org.testng.SuiteRunner.runTest(SuiteRunner.java:366)
	at org.testng.SuiteRunner.runSequentially(SuiteRunner.java:361)
	at org.testng.SuiteRunner.privateRun(SuiteRunner.java:319)
	at org.testng.SuiteRunner.run(SuiteRunner.java:268)
	at org.testng.SuiteRunnerWorker.runSuite(SuiteRunnerWorker.java:52)
	at org.testng.SuiteRunnerWorker.run(SuiteRunnerWorker.java:86)
	at org.testng.TestNG.runSuitesSequentially(TestNG.java:1225)
	at org.testng.TestNG.runSuitesLocally(TestNG.java:1150)
	at org.testng.TestNG.runSuites(TestNG.java:1075)
	at org.testng.TestNG.run(TestNG.java:1047)
	at org.testng.remote.AbstractRemoteTestNG.run(AbstractRemoteTestNG.java:126)
	at org.testng.remote.RemoteTestNG.initAndRun(RemoteTestNG.java:137)
	at org.testng.remote.RemoteTestNG.main(RemoteTestNG.java:58)
]]>
            </full-stacktrace>
          </exception> <!-- java.lang.AssertionError -->
          <reporter-output>
          </reporter-output>
        </test-method> <!-- Test2 -->
        <test-method status="FAIL" signature="Test2()[pri:0, instance:MyTests.RunTimeTests@66d2e7d9]" name="Test2" duration-ms="3" started-at="2019-08-21T22:45:44Z" finished-at="2019-08-21T22:45:44Z">
          <exception class="java.lang.AssertionError">
            <message>
              <![CDATA[expected [true] but found [false]]]>
            </message>
            <full-stacktrace>
              <![CDATA[java.lang.AssertionError: expected [true] but found [false]
	at org.testng.Assert.fail(Assert.java:94)
	at org.testng.Assert.failNotEquals(Assert.java:513)
	at org.testng.Assert.assertEqualsImpl(Assert.java:135)
	at org.testng.Assert.assertEquals(Assert.java:116)
	at org.testng.Assert.assertEquals(Assert.java:305)
	at org.testng.Assert.assertEquals(Assert.java:315)
	at MyTests.RunTimeTests.Test2(RunTimeTests.java:18)
	at sun.reflect.NativeMethodAccessorImpl.invoke0(Native Method)
	at sun.reflect.NativeMethodAccessorImpl.invoke(NativeMethodAccessorImpl.java:62)
	at sun.reflect.DelegatingMethodAccessorImpl.invoke(DelegatingMethodAccessorImpl.java:43)
	at java.lang.reflect.Method.invoke(Method.java:498)
	at org.testng.internal.MethodInvocationHelper.invokeMethod(MethodInvocationHelper.java:86)
	at org.testng.internal.Invoker.invokeMethod(Invoker.java:646)
	at org.testng.internal.Invoker.retryFailed(Invoker.java:970)
	at org.testng.internal.Invoker.invokeTestMethods(Invoker.java:1149)
	at org.testng.internal.TestMethodWorker.invokeTestMethods(TestMethodWorker.java:129)
	at org.testng.internal.TestMethodWorker.run(TestMethodWorker.java:112)
	at org.testng.TestRunner.privateRun(TestRunner.java:778)
	at org.testng.TestRunner.run(TestRunner.java:632)
	at org.testng.SuiteRunner.runTest(SuiteRunner.java:366)
	at org.testng.SuiteRunner.runSequentially(SuiteRunner.java:361)
	at org.testng.SuiteRunner.privateRun(SuiteRunner.java:319)
	at org.testng.SuiteRunner.run(SuiteRunner.java:268)
	at org.testng.SuiteRunnerWorker.runSuite(SuiteRunnerWorker.java:52)
	at org.testng.SuiteRunnerWorker.run(SuiteRunnerWorker.java:86)
	at org.testng.TestNG.runSuitesSequentially(TestNG.java:1225)
	at org.testng.TestNG.runSuitesLocally(TestNG.java:1150)
	at org.testng.TestNG.runSuites(TestNG.java:1075)
	at org.testng.TestNG.run(TestNG.java:1047)
	at org.testng.remote.AbstractRemoteTestNG.run(AbstractRemoteTestNG.java:126)
	at org.testng.remote.RemoteTestNG.initAndRun(RemoteTestNG.java:137)
	at org.testng.remote.RemoteTestNG.main(RemoteTestNG.java:58)
]]>
            </full-stacktrace>
          </exception> <!-- java.lang.AssertionError -->
          <reporter-output>
          </reporter-output>
        </test-method> <!-- Test2 -->
        <test-method status="PASS" signature="Test3()[pri:0, instance:MyTests.RunTimeTests@66d2e7d9]" name="Test3" duration-ms="2" started-at="2019-08-21T22:45:44Z" finished-at="2019-08-21T22:45:44Z">
          <reporter-output>
          </reporter-output>
        </test-method> <!-- Test3 -->
      </class> <!-- MyTests.RunTimeTests -->
    </test> <!-- RetryMultipleFailedTestCases -->
  </suite> <!-- RetryFailedTestSuite -->
</testng-results>
